<?xml version="1.0" ?>

<robot name="Dynamixel">
<!-- pi   = 3.14159265359 -->
<!-- pi/2 = 1.57079632675 -->

  <link name="base_link">
    <visual>
      <origin rpy="0 0 0" xyz="0 0 -0.0025"/>
      <geometry name="link0">
        <mesh filename="robot_descriptions/custom_man_description/meshes/visual/link0.dae"/>
      </geometry>
      <material name="">
        <color rgba="0.5 0.5 0.5 0.5"/>
      </material>
    </visual>
  </link>

  <joint name="joint_1" type="revolute">
    <origin rpy ="0 0 0" xyz="0 0 0.06"/>
    <parent link="base_link"/>
    <child  link="link_1"/>
    <axis    xyz ="0 0 1"/>
    <limit effort="0" lower="-5" upper="5" velocity="3.14"/>
  </joint>

  <link name="link_1">
    <visual>
      <origin rpy="0 0 0" xyz="0 0 -0.0625"/>
      <geometry>
        <mesh filename="robot_descriptions/custom_man_description/meshes/visual/link1.dae"/>
      </geometry>
      <material name="">
        <color rgba="0.5 0.5 0.5 0.5"/>
      </material>
    </visual>
  </link>

  <joint name="joint_2" type="revolute">
    <origin rpy="1.57079632675 0 0" xyz="0 0 0"/>
    <parent link="link_1"/>
    <child  link="link_2"/>
    <axis   xyz="0 0 1"/>
    <limit effort="0" lower="-5" upper="5" velocity="3.14"/>
  </joint>

  <link name="link_2">
    <visual>
      <origin rpy="-1.57079632675 0 -1.57079632675" xyz="-0.0625 0 0"/>
      <geometry>
        <mesh filename="robot_descriptions/custom_man_description/meshes/visual/link2.stl"/>
      </geometry>
      <material name="">
        <color rgba="0.5 0.5 0.5  0.5"/>
      </material>
    </visual>
  </link>

  <joint name="joint_3" type="revolute">
    <origin rpy="0 0 1.57079632675" xyz="0.15 0 0"/>
    <parent link="link_2"/>
    <child  link="link_3"/>
    <axis   xyz="0 0 1"/>
    <limit effort="0" lower="-5" upper="5" velocity="3.14"/>
  </joint>

  <link name="link_3">
    <visual>
      <origin rpy="1.57079632675 3.14159265359 0" xyz="0 0.2125 0"/>
      <geometry>
        <mesh filename="robot_descriptions/custom_man_description/meshes/visual/link3.stl"/>
      </geometry>
      <material name="">
        <color rgba="0.5 0.5 0.5 0.5"/>
      </material>
    </visual>
  </link>
  
  <joint name="joint_4" type="revolute">
    <origin rpy="1.57079632675 0 0" xyz="0.07 -0.13 0"/>
    <parent link="link_3"/>
    <child  link="link_4"/>
    <axis   xyz="0 0 1"/>
    <limit effort="0" lower="-5" upper="5" velocity="3.14"/>
  </joint>

  <link name="link_4">
    <visual>
      <origin rpy="0 0 0" xyz="0.07 0 -0.3425"/>
      <geometry>
        <mesh filename="robot_descriptions/custom_man_description/meshes/visual/link4.stl"/>
      </geometry>
      <material name="">
        <color rgba="0.5 0.5 0.5 0.5"/>
      </material>
    </visual>
  </link>

  <joint name="joint_5" type="revolute">
    <origin rpy="-1.57079632675 0 0" xyz="0 0 0"/>
    <parent link="link_4"/>
    <child  link="link_5"/>
    <axis   xyz="0 0 1"/>
    <limit effort="0" lower="-5" upper="5" velocity="3.14"/>
  </joint>

  <link name="link_5">
    <visual>
      <origin rpy="1.57079632675 0 -1.57079632675" xyz="0.3425 -0.07 0"/>
      <geometry>
        <mesh filename="robot_descriptions/custom_man_description/meshes/visual/link5.stl"/>
      </geometry>
      <material name="">
        <color rgba="0.5 0.5 0.5 0.5"/>
      </material>
    </visual>
  </link>
  
  <joint name="joint_6" type="revolute">
    <origin rpy="1.57079632675 0 0" xyz="0 -0.031 0"/>
    <parent link="link_5"/>
    <child  link="link_6"/>
    <axis   xyz="0 0 1"/>
    <limit effort="0" lower="-5" upper="5" velocity="3.14"/>
  </joint>

  <link name="link_6">
    <visual>
      <origin rpy="0 1.57079632675 0" xyz="-0.3425 0 -0.044"/>
      <geometry>
        <mesh filename="robot_descriptions/custom_man_description/meshes/visual/link6.stl"/>
      </geometry>
      <material name="">
        <color rgba="0.5 0.5 0.5 0.5"/>
      </material>
    </visual>
  </link>

  <joint name="j6_ee" type="fixed">
    <origin rpy="0 0 0" xyz="0 0 0.064"/>
    <parent link="link_6"/>
    <child  link="end_effector_link"/>
    <axis   xyz="0 0 1"/>
    <limit effort="0" lower="-5" upper="5" velocity="3.14"/>
  </joint>

  <link name="end_effector_link">
    <visual>
      <origin rpy="0 -1.57079632675 0" xyz="0.3425 0 -0.02525"/>
      <geometry>
        <mesh filename="robot_descriptions/custom_man_description/meshes/visual/gripper.stl"/>
      </geometry>
      <material name="">
        <color rgba="0.5 0.5 0.5 0.5"/>
      </material>
    </visual>
  </link>
    
</robot>

