<?xml version="1.0" ?>
<robot name="ur3e" xmlns:xacro="http://www.ros.org/wiki/xacro">

  <link name="world">
    <origin rpy="0.0 0.0 0.0" xyz="0.0 0.0 0.0"/>
  </link>
  
  
  <joint name="world_to_base_joint" type="fixed">
    <parent link="world"/>
    <child link="base_link"/>
    <origin rpy="0.0 0.0 0.0" xyz="0.0 0.0 0.0"/>
    <axis xyz="0 0 1"/>
  </joint>


  <link name="base_link">
    <visual>
      <origin rpy="0 0 0" xyz="0 0 0"/>
      <geometry>
        <mesh filename="robot_descriptions/ur_description/meshes/ur3e/visual/base.dae"/>
      </geometry>
      <!-- <material name="LightGrey">
        <color rgba="0.7 0.7 0.7 1.0"/>
      </material> -->
    </visual>
    <collision>
      <origin rpy="0 0 0" xyz="0 0 0"/>
      <geometry>
        <mesh filename="robot_descriptions/ur_description/meshes/ur3e/collision/base.stl"/>
      </geometry>
    </collision>
    <inertial>
      <mass value="2.0"/>
      <origin rpy="0 0 0" xyz="0 0 0"/>
      <inertia ixx="0.0030531654454" ixy="0.0" ixz="0.0" iyy="0.0030531654454" iyz="0.0" izz="0.005625"/>
    </inertial>
  </link>


  <joint name="shoulder_pan_joint" type="revolute">
    <parent link="base_link"/>
    <child link="shoulder_link"/>
    <origin rpy="0 0 0" xyz="0 0 0.15185"/>
    <axis xyz="0 0 1"/>
    <limit effort="56.0" lower="-6.283185307179586" upper="6.283185307179586" velocity="3.141592653589793"/>
    <dynamics damping="0" friction="0"/>
  </joint>

  
  <link name="shoulder_link">
    <visual>
      <origin rpy="0 0 3.141592653589793" xyz="0 0 0"/>
      <geometry>
        <mesh filename="robot_descriptions/ur_description/meshes/ur3e/visual/shoulder.dae"/>
      </geometry>
      <!-- <material name="LightGrey">
        <color rgba="0.7 0.7 0.7 1.0"/>
      </material> -->
    </visual>
    <collision>
      <origin rpy="0 0 3.141592653589793" xyz="0 0 0"/>
      <geometry>
        <mesh filename="robot_descriptions/ur_description/meshes/ur3e/collision/shoulder.stl"/>
      </geometry>
    </collision>
    <inertial>
      <mass value="2.0"/>
      <origin rpy="0 0 0" xyz="0 0 0"/>
      <inertia ixx="0.008093163429399999" ixy="0.0" ixz="0.0" iyy="0.008093163429399999" iyz="0.0" izz="0.005625"/>
    </inertial>
  </link>


  <joint name="shoulder_lift_joint" type="revolute">
    <parent link="shoulder_link"/>
    <child link="upper_arm_link"/>
    <origin rpy="1.570796327 0 0" xyz="0 0 0"/>
    <axis xyz="0 0 1"/>
    <limit effort="56.0" lower="-6.283185307179586" upper="6.283185307179586" velocity="3.141592653589793"/>
    <dynamics damping="0" friction="0"/>
  </joint>


  <link name="upper_arm_link">
    <visual>
      <origin rpy="1.5707963267948966 0 -1.5707963267948966" xyz="0 0 0.12"/>
      <geometry>
        <mesh filename="robot_descriptions/ur_description/meshes/ur3e/visual/upperarm.dae"/>
      </geometry>
      <!-- <material name="LightGrey">
        <color rgba="0.7 0.7 0.7 1.0"/>
      </material> -->
    </visual>
    <collision>
      <origin rpy="1.5707963267948966 0 -1.5707963267948966" xyz="0 0 0.12"/>
      <geometry>
        <mesh filename="robot_descriptions/ur_description/meshes/ur3e/collision/upperarm.stl"/>
      </geometry>
    </collision>
    <inertial>
      <mass value="3.42"/>
      <origin rpy="0 1.5707963267948966 0" xyz="-0.121825 0.0 0.12"/>
      <inertia ixx="0.021728483221103233" ixy="0.0" ixz="0.0" iyy="0.021728483221103233" iyz="0.0" izz="0.00961875"/>
    </inertial>
  </link>


  <joint name="elbow_joint" type="revolute">
    <parent link="upper_arm_link"/>
    <child link="forearm_link"/>
    <origin rpy="0 0 0" xyz="-0.24355 0 0"/>
    <axis xyz="0 0 1"/>
    <limit effort="28.0" lower="-3.141592653589793" upper="3.141592653589793" velocity="3.141592653589793"/>
    <dynamics damping="0" friction="0"/>
  </joint>


  <link name="forearm_link">
    <visual>
      <origin rpy="1.5707963267948966 0 -1.5707963267948966" xyz="0 0 0.027"/>
      <geometry>
        <mesh filename="robot_descriptions/ur_description/meshes/ur3e/visual/forearm.dae"/>
      </geometry>
      <!-- <material name="LightGrey">
        <color rgba="0.7 0.7 0.7 1.0"/>
      </material> -->
    </visual>
    <collision>
      <origin rpy="1.5707963267948966 0 -1.5707963267948966" xyz="0 0 0.027"/>
      <geometry>
        <mesh filename="robot_descriptions/ur_description/meshes/ur3e/collision/forearm.stl"/>
      </geometry>
    </collision>
    <inertial>
      <mass value="1.26"/>
      <origin rpy="0 1.5707963267948966 0" xyz="-0.1066 0.0 0.027"/>
      <inertia ixx="0.0065445675821719194" ixy="0.0" ixz="0.0" iyy="0.0065445675821719194" iyz="0.0" izz="0.00354375"/>
    </inertial>
  </link>


  <joint name="wrist_1_joint" type="revolute">
    <parent link="forearm_link"/>
    <child link="wrist_1_link"/>
    <origin rpy="0 0 0" xyz="-0.2132 0 0.13105"/>
    <axis xyz="0 0 1"/>
    <limit effort="12.0" lower="-6.283185307179586" upper="6.283185307179586" velocity="6.283185307179586"/>
    <dynamics damping="0" friction="0"/>
  </joint>


  <link name="wrist_1_link">
    <visual>
      <origin rpy="1.5707963267948966 0 0" xyz="0 0 -0.104"/>
      <geometry>
        <mesh filename="robot_descriptions/ur_description/meshes/ur3e/visual/wrist1.dae"/>
      </geometry>
      <!-- <material name="LightGrey">
        <color rgba="0.7 0.7 0.7 1.0"/>
      </material> -->
    </visual>
    <collision>
      <origin rpy="1.5707963267948966 0 0" xyz="0 0 -0.104"/>
      <geometry>
        <mesh filename="robot_descriptions/ur_description/meshes/ur3e/collision/wrist1.stl"/>
      </geometry>
    </collision>
    <inertial>
      <mass value="0.8"/>
      <origin rpy="0 0 0" xyz="0 0 0"/>
      <inertia ixx="0.002084999166" ixy="0.0" ixz="0.0" iyy="0.002084999166" iyz="0.0" izz="0.00225"/>
    </inertial>
  </link>


  <joint name="wrist_2_joint" type="revolute">
    <parent link="wrist_1_link"/>
    <child link="wrist_2_link"/>
    <origin rpy="1.570796327 0 0" xyz="0 -0.08535 0.0"/>
    <axis xyz="0 0 1"/>
    <limit effort="12.0" lower="-6.283185307179586" upper="6.283185307179586" velocity="6.283185307179586"/>
    <dynamics damping="0" friction="0"/>
  </joint>


  <link name="wrist_2_link">
    <visual>
      <origin rpy="0 0 0" xyz="0 0 -0.08535"/>
      <geometry>
        <mesh filename="robot_descriptions/ur_description/meshes/ur3e/visual/wrist2.dae"/>
      </geometry>
      <!-- <material name="LightGrey">
        <color rgba="0.7 0.7 0.7 1.0"/>
      </material> -->
    </visual>
    <collision>
      <origin rpy="0 0 0" xyz="0 0 -0.08535"/>
      <geometry>
        <mesh filename="robot_descriptions/ur_description/meshes/ur3e/collision/wrist2.stl"/>
      </geometry>
    </collision>
    <inertial>
      <mass value="0.8"/>
      <origin rpy="0 0 0" xyz="0 0 0"/>
      <inertia ixx="0.002084999166" ixy="0.0" ixz="0.0" iyy="0.002084999166" iyz="0.0" izz="0.00225"/>
    </inertial>
  </link>


  <joint name="wrist_3_joint" type="revolute">
    <parent link="wrist_2_link"/>
    <child link="wrist_3_link"/>
    <origin rpy="-1.570796326589793 0.0 0.0" xyz="0 0.0921 -1.8890025766262e-11"/>
    <axis xyz="0 0 1"/>
    <limit effort="12.0" lower="-6.283185307179586" upper="6.283185307179586" velocity="6.283185307179586"/>
    <dynamics damping="0" friction="0"/>
  </joint>


  <link name="wrist_3_link">
    <visual>
      <origin rpy="1.5707963267948966 0 0" xyz="0 0 -0.0921"/>
      <geometry>
        <mesh filename="robot_descriptions/ur_description/meshes/ur3e/visual/wrist3.dae"/>
      </geometry>
      <!-- <material name="LightGrey">
        <color rgba="0.7 0.7 0.7 1.0"/>
      </material> -->
    </visual>
    <collision>
      <origin rpy="1.5707963267948966 0 0" xyz="0 0 -0.0921"/>
      <geometry>
        <mesh filename="robot_descriptions/ur_description/meshes/ur3e/collision/wrist3.stl"/>
      </geometry>
    </collision>
    <inertial>
      <mass value="0.35"/>
      <origin rpy="0 0 0" xyz="0.0 0.0 -0.02"/>
      <inertia ixx="0.00013626661215999998" ixy="0.0" ixz="0.0" iyy="0.00013626661215999998" iyz="0.0" izz="0.0001792"/>
    </inertial>
  </link>

</robot>

  <!-- <joint name="ee_fixed_joint" type="fixed">
    <parent link="wrist_3_link"/>
    <child link="gripper_base"/>
    <origin rpy="0.0 0.0 1.570796325" xyz="0.0 0.0 0.0"/>
  </joint>


  <link name="gripper_base">
    <visual>
        <origin rpy="0.0 0.0 0.0" xyz="0.0 0.0 0.0" />
   	    <geometry>
	        <mesh filename="robot_descriptions/gripper_description/gripper_description/meshes/soft_gripper_base_down.stl"/>
	    </geometry>
    </visual>
    <collision>
        <origin rpy="0.0 0.0 0.0" xyz="0.0 0.0 0.0" />
        <geometry>
	        <mesh filename="robot_descriptions/gripper_description/gripper_description/meshes/soft_gripper_base_down.stl"/>
	    </geometry>
    </collision>
    <inertial>
	    <origin xyz="2.073e-05   1.45286e-03  -1.1049e-03" rpy="0.0 0.0 0.0" />
	    <mass value="0.168" />
	    <inertia ixx="6.69695624e-05" ixy="5.21511788e-09" ixz="-2.74383009e-08" iyy="7.85088161e-05" iyz="5.41105193e-07" izz="1.41819717e-04" />
    </inertial>
  </link> -->

  <!-- ROS-Industrial 'base' frame: base_link to UR 'Base' Coordinates transform -->
  
  <!-- <link name="base"/>
  <joint name="base_link-base_fixed_joint" type="fixed"> -->
    <!-- Note the rotation over Z of pi radians: as base_link is REP-103
           aligned (ie: has X+ forward, Y+ left and Z+ up), this is needed
           to correctly align 'base' with the 'Base' coordinate system of
           the UR controller.
      -->
    <!-- <origin rpy="0 0 3.141592653589793" xyz="0 0 0"/>
    <parent link="base_link"/>
    <child link="base"/>
  </joint> -->
  
  <!-- ROS-Industrial 'flange' frame: attachment point for EEF models -->
  
  <!-- <link name="flange"/>
  <joint name="wrist_3-flange" type="fixed">
    <parent link="wrist_3_link"/>
    <child link="flange"/>
    <origin rpy="0 -1.5707963267948966 -1.5707963267948966" xyz="0 0 0"/>
  </joint> -->
  
  <!-- ROS-Industrial 'tool0' frame: all-zeros tool frame -->
  
  <!-- <link name="tool0"/>
  <joint name="flange-tool0" type="fixed"> -->
    
    <!-- default toolframe: X+ left, Y+ up, Z+ front -->
    
    <!-- <origin rpy="1.5707963267948966 0 1.5707963267948966" xyz="0 0 0"/>
    <parent link="flange"/>
    <child link="tool0"/>
  </joint> -->
