<?xml version="1.0" ?>
<robot name="ur5" xmlns:xacro="http://www.ros.org/wiki/xacro">
  <!-- ur5 -->
  <!-- Inertia parameters -->
  <!-- This mass might be incorrect -->
  <!-- Kinematic model -->
  <!-- Properties from urcontrol.conf -->
  <!-- pi:   3.1415926535 -->
  <!-- pi/2: 1.570796327  -->
  <!--
    DH for UR5:
    a     = [           0,  -0.42500, -0.39225,           0,            0,       0]
    d     = [    0.089159,         0,        0,     0.10915,      0.09465,  0.0823]
    alpha = [ 1.570796327,         0,        0, 1.570796327, -1.570796327,       0]
    q_home_offset = [0, -1.570796327, 0, -1.570796327, 0, 0]
    joint_direction = [-1, -1, 1, 1, 1, 1]
    mass            = [3.7000, 8.3930, 2.2750, 1.2190, 1.2190, 0.1879]
    center_of_mass  = [ [0, -0.02561, 0.00193], [0.2125, 0, 0.11336], [0.11993, 0.0, 0.0265], [0, -0.0018, 0.01634], [0, 0.0018,0.01634], [0, 0, -0.001159] ]
  -->

  <!-- Arbitrary offsets for shoulder/elbow joints -->
  <!-- measured from model -->
  <!-- measured from model -->
  
  <!-- link lengths used in model -->
  <!--property name="shoulder_height" value="0.089159" /-->
  <!--property name="shoulder_offset" value="0.13585" /-->
  <!-- shoulder_offset - elbow_offset + wrist_1_length = 0.10915 -->
  <!--property name="upper_arm_length" value="0.42500" /-->
  <!--property name="elbow_offset" value="0.1197" /-->
  
  <!-- CAD measured -->
  <!--property name="forearm_length" value="0.39225" /-->
  <!--property name="wrist_1_length" value="0.093" /-->
  
  <!-- CAD measured -->
  <!--property name="wrist_2_length" value="0.09465" /-->
  <!-- In CAD this distance is 0.930, but in the spec it is 0.09465 -->
  <!--property name="wrist_3_length" value="0.0823" /-->
  
  <link name="world"/>
  
  
  <joint name="world_joint" type="fixed">
    <parent link="world"/>
    <child link="base_link"/>
    <origin rpy="0.0 0.0 0.0" xyz="0.0 0.0 0.0"/>
  </joint>


  <link name="base_link">
    <visual>
      <origin rpy="0.0 0.0 0.0" xyz="0.0 0.0 0.0" />
      <geometry>
        <mesh filename="robot_descriptions/ur_description/meshes/ur5/visual/base.dae"/>
      </geometry>
      <!--material name="LightGrey">
        <color rgba="0.7 0.7 0.7 1.0"/>
      </material-->
    </visual>
    <collision>
      <origin rpy="0.0 0.0 0.0" xyz="0.0 0.0 0.0" />
      <geometry>
        <mesh filename="robot_descriptions/ur_description/meshes/ur5/collision/base.stl"/>
      </geometry>
    </collision>
    <inertial>
      <mass value="4.0"/>
      <origin rpy="0 0 0" xyz="0.0 0.0 0.0"/>
      <inertia ixx="0.00443333156" ixy="0.0" ixz="0.0" iyy="0.00443333156" iyz="0.0" izz="0.0072"/>
    </inertial>
  </link>


  <joint name="shoulder_pan_joint" type="revolute">
    <parent link="base_link"/>
    <child link="shoulder_link"/>
    <origin rpy="0.0 0.0 0.0" xyz="0.0 0.0 0.089159"/>
    <axis xyz="0 0 1"/>
    <limit effort="150.0" lower="-3.14159265" upper="3.14159265" velocity="3.15"/>
    <dynamics damping="0.0" friction="0.0"/>
  </joint>


  <link name="shoulder_link">
    <visual>
      <origin rpy="0.0 0.0 3.14159265359" xyz="0.0 0.0 0.0" />
      <geometry>
        <mesh filename="robot_descriptions/ur_description/meshes/ur5/visual/shoulder.dae"/>
      </geometry>
      <!--material name="LightGrey">
        <color rgba="0.7 0.7 0.7 1.0"/>
      </material-->
    </visual>
    <collision>
      <origin rpy="0.0 0.0 3.14159265359" xyz="0.0 0.0 0.0" />
      <geometry>
        <mesh filename="robot_descriptions/ur_description/meshes/ur5/collision/shoulder.stl"/>
      </geometry>
    </collision>
    <inertial>
      <mass value="3.7"/>
      <origin rpy="0 0 0" xyz="0.0 0.0 0.0"/>
      <inertia ixx="0.010267495893" ixy="0.0" ixz="0.0" iyy="0.010267495893" iyz="0.0" izz="0.00666"/>
    </inertial>
  </link>


  <joint name="shoulder_lift_joint" type="revolute">
    <parent link="shoulder_link"/>
    <child link="upper_arm_link"/>
    <origin rpy="1.570796325 1.570796327 0.0" xyz="0.0 0.0 0.0"/>
    <axis xyz="0 0 1"/>
    <limit effort="150.0" lower="-3.14159265" upper="3.14159265" velocity="3.15"/>
    <dynamics damping="0.0" friction="0.0"/>
  </joint>


  <link name="upper_arm_link">
    <visual>
      <origin rpy="1.570796325 0.0 -1.570796325" xyz="0.0 0.0 0.13585"/>
      <geometry>
        <mesh filename="robot_descriptions/ur_description/meshes/ur5/visual/upperarm.dae"/>
      </geometry>
      <!--material name="LightGrey">
        <color rgba="0.7 0.7 0.7 1.0"/>
      </material-->
    </visual>
    <collision>
      <origin rpy="1.570796325 0.0 -1.570796325" xyz="0.0 0.0 0.13585"/>
      <geometry>
        <mesh filename="robot_descriptions/ur_description/meshes/ur5/collision/upperarm.stl"/>
      </geometry>
    </collision>
    <inertial>
      <mass value="8.393"/>
      <origin rpy="0 0 0" xyz="0.0 0.0 0.28"/>
      <inertia ixx="0.22689067591" ixy="0.0" ixz="0.0" iyy="0.22689067591" iyz="0.0" izz="0.0151074"/>
    </inertial>
  </link>


  <joint name="elbow_joint" type="revolute">
    <parent link="upper_arm_link"/>
    <child link="forearm_link"/>
    <origin rpy="0.0 0.0 0.0" xyz="-0.425 0.0 0.0"/>
    <axis xyz="0 0 1"/>
    <limit effort="150.0" lower="-3.14159265" upper="3.14159265" velocity="3.15"/>
    <dynamics damping="0.0" friction="0.0"/>
  </joint>


  <link name="forearm_link">
    <visual>
      <origin rpy="1.570796325 0.0 -1.570796325" xyz="0.0 0.0 0.0165" />
      <geometry>
        <mesh filename="robot_descriptions/ur_description/meshes/ur5/visual/forearm.dae"/>
      </geometry>
      <!--material name="LightGrey">
        <color rgba="0.7 0.7 0.7 1.0"/>
      </material-->
    </visual>
    <collision>
      <origin rpy="1.570796325 0.0 -1.570796325" xyz="0.0 0.0 0.0165" />
      <geometry>
        <mesh filename="robot_descriptions/ur_description/meshes/ur5/collision/forearm.stl"/>
      </geometry>
    </collision>
    <inertial>
      <mass value="2.275"/>
      <origin rpy="0 0 0" xyz="0.0 0.0 0.25"/>
      <inertia ixx="0.049443313556" ixy="0.0" ixz="0.0" iyy="0.049443313556" iyz="0.0" izz="0.004095"/>
    </inertial>
  </link>


  <joint name="wrist_1_joint" type="revolute">
    <parent link="forearm_link"/>
    <child link="wrist_1_link"/>
    <origin rpy="0.0 0.0 -1.570796327" xyz="-0.39225 0.0 0.10915"/>
    <axis xyz="0 0 1"/>
    <limit effort="28.0" lower="-3.14159265" upper="3.14159265" velocity="3.2"/>
    <dynamics damping="0.0" friction="0.0"/>
  </joint>


  <link name="wrist_1_link">
    <visual>
      <origin rpy="1.570796325 0.0 0.0" xyz="0.0 0.0 -0.093" />
      <geometry>
        <mesh filename="robot_descriptions/ur_description/meshes/ur5/visual/wrist1.dae"/>
      </geometry>
      <!--material name="LightGrey">
        <color rgba="0.7 0.7 0.7 1.0"/>
      </material-->
    </visual>
    <collision>
      <origin rpy="1.570796325 0.0 0.0" xyz="0.0 0.0 -0.093" />
      <geometry>
        <mesh filename="robot_descriptions/ur_description/meshes/ur5/collision/wrist1.stl"/>
      </geometry>
    </collision>
    <inertial>
      <mass value="1.219"/>
      <origin rpy="0 0 0" xyz="0.0 0.0 0.0"/>
      <inertia ixx="0.111172755531" ixy="0.0" ixz="0.0" iyy="0.111172755531" iyz="0.0" izz="0.21942"/>
    </inertial>
  </link>


  <joint name="wrist_2_joint" type="revolute">
    <parent link="wrist_1_link"/>
    <child link="wrist_2_link"/>
    <origin rpy="1.570796325 0.0 0.0" xyz="0.0 -0.09465 0.0"/>
    <axis xyz="0 0 1"/>
    <limit effort="28.0" lower="-3.14159265" upper="3.14159265" velocity="3.2"/>
    <dynamics damping="0.0" friction="0.0"/>
  </joint>


  <link name="wrist_2_link">
    <visual>
      <origin rpy="0.0 0.0 0.0" xyz="0.0 0.0 -0.09465" />
      <geometry>
        <mesh filename="robot_descriptions/ur_description/meshes/ur5/visual/wrist2.dae"/>
      </geometry>
      <!--material name="LightGrey">
        <color rgba="0.7 0.7 0.7 1.0"/>
      </material-->
    </visual>
    <collision>
      <origin rpy="0.0 0.0 0.0" xyz="0.0 0.0 -0.09465" />
      <geometry>
        <mesh filename="robot_descriptions/ur_description/meshes/ur5/collision/wrist2.stl"/>
      </geometry>
    </collision>
    <inertial>
      <mass value="1.219"/>
      <origin rpy="0 0 0" xyz="0.0 0.0 0.0"/>
      <inertia ixx="0.111172755531" ixy="0.0" ixz="0.0" iyy="0.111172755531" iyz="0.0" izz="0.21942"/>
    </inertial>
  </link>


  <joint name="wrist_3_joint" type="revolute">
    <parent link="wrist_2_link"/>
    <child link="wrist_3_link"/>
    <origin rpy="-1.570796325 0.0 0.0" xyz="0.0 0.0823 0.0"/>
    <axis xyz="0 0 1"/>
    <limit effort="28.0" lower="-3.14159265" upper="3.14159265" velocity="3.2"/>
    <dynamics damping="0.0" friction="0.0"/>
  </joint>



  <link name="wrist_3_link">
    <visual>
      <origin rpy="1.570796325 0.0 0.0" xyz="0.0 0.0 -0.0823" />
      <geometry>
        <mesh filename="robot_descriptions/ur_description/meshes/ur5/visual/wrist3.dae"/>
      </geometry>
      <!--material name="LightGrey">
        <color rgba="0.7 0.7 0.7 1.0"/>
      </material-->
    </visual>
    <collision>
      <origin rpy="1.570796325 0.0 0.0" xyz="0.0 0.0 -0.0823" />
      <geometry>
        <mesh filename="robot_descriptions/ur_description/meshes/ur5/collision/wrist3.stl"/>
      </geometry>
    </collision>
    <inertial>
      <mass value="0.1879"/>
      <origin rpy="0 0 0" xyz="0.0 0.0 0.0"/>
      <inertia ixx="0.0171364731454" ixy="0.0" ixz="0.0" iyy="0.0171364731454" iyz="0.0" izz="0.033822"/>
    </inertial>
  </link>


  <joint name="ee_fixed_joint" type="fixed">
    <parent link="wrist_3_link"/>
    <child link="gripper_base"/>
    <origin rpy="0.0 0.0 1.570796325" xyz="0.0 0.0 0.0"/>
  </joint>


  <link name="gripper_base">
    <visual>
        <origin rpy="0.0 0.0 0.0" xyz="0.0 0.0 0.0" />
   	    <geometry>
	        <mesh filename="robot_descriptions/gripper_description/gripper_description/meshes/soft_gripper_base_down.stl"/>
	    </geometry>
    </visual>
    <collision>
        <origin rpy="0.0 0.0 0.0" xyz="0.0 0.0 0.0" />
        <geometry>
	        <mesh filename="robot_descriptions/gripper_description/gripper_description/meshes/soft_gripper_base_down.stl"/>
	    </geometry>
    </collision>
    <inertial>
	    <origin xyz="2.073e-05   1.45286e-03  -1.1049e-03" rpy="0.0 0.0 0.0" />
	    <mass value="0.168" />
	    <inertia ixx="6.69695624e-05" ixy="5.21511788e-09" ixz="-2.74383009e-08" iyy="7.85088161e-05" iyz="5.41105193e-07" izz="1.41819717e-04" />
    </inertial>
  </link>


  <joint name="fixed_ee_gripper" type="fixed">
		<origin xyz="0.0 0.0 0.145" rpy="0.0 0.0 0.0"/>
		<parent link="gripper_base"/>
		<child  link="tool0"/>
  </joint>


  <!-- TOOL CENTER PPOINT -->
  <link name="tool0"/>
    
  
  <!-- _______________FIRST GRIPPER FINGER_______________ -->
  <joint name="hand1_joint" type="revolute">
    <parent link="gripper_base"/>
    <child link="hand1_link"/>
    <axis xyz="1 0 0"/>
    <origin xyz="0.0 -0.028 0.09" rpy="0.0 0.0 0.0" />
    <limit effort="50" velocity="10.0" lower="-1." upper="1." />
  </joint>

  <link name="hand1_link">
	<visual>
	    <origin rpy="0.0 0.0 0.0" xyz="0.0 0.0 0.0" />
		<geometry>
		    <mesh filename="robot_descriptions/gripper_description/gripper_description/meshes/soft_gripper_finger1.stl"/>
		</geometry>
	</visual>
	<collision>
	    <origin rpy="0.0 0.0 0.0" xyz="0.0 0.0 0.0" />
		<geometry>
		    <mesh filename="robot_descriptions/gripper_description/gripper_description/meshes/soft_gripper_finger1.stl"/>
		</geometry>
	</collision>
    <inertial>
		<origin xyz="2.073e-05   1.45286e-03  -1.1049e-03" rpy="0 0 0" />
		<mass value="0.168" />
		<inertia ixx="6.69695624e-05" ixy="5.21511788e-09" ixz="-2.74383009e-08" iyy="7.85088161e-05" iyz="5.41105193e-07" izz="1.41819717e-04" />
	</inertial>
  </link>

  <joint name="hand1_joint2" type="fixed">
	<origin xyz="0.0 0.009 0.042" rpy="0.0 0.0 0.0" />
	<parent link="hand1_link" />
	<child link="hand1_link2" />
  </joint>

  <link name="hand1_link2">
	<visual>
		<geometry>
		  <mesh filename="robot_descriptions/gripper_description/gripper_description/meshes/soft_gripper_finger2.stl" />
		</geometry>
	    <material name="Blue" />
	</visual>
	<collision>
		<geometry>
		  <mesh filename="robot_descriptions/gripper_description/gripper_description/meshes/soft_gripper_finger2.stl" />
		</geometry>
	</collision>
	<inertial>
	    <origin xyz="2.073e-05 1.45286e-03 -1.1049e-03" rpy="0.0 0.0 0.0" />
		<mass value="0.168" />
		<inertia ixx="6.69695624e-05" ixy="5.21511788e-09" ixz="-2.74383009e-08" iyy="7.85088161e-05" iyz="5.41105193e-07" izz="1.41819717e-04" />
	</inertial>
  </link>

  <!-- ______________SECOND GRIPPER FINGER_______________ -->
  <joint name="hand2_joint" type="revolute">
    <parent link="gripper_base"/>
    <child link="hand2_link"/>
    <axis xyz="1 0 0"/>
    <origin xyz="0.0 0.028 0.09" rpy=" 0.0 0.0 -3.14159265" />
    <limit effort="50" velocity="10.0" lower="-1." upper="1." />
  </joint>

  <link name="hand2_link">
	<visual>
	    <origin rpy="0 0 0" xyz="0 0 0" />
		<geometry>
		    <mesh filename="robot_descriptions/gripper_description/gripper_description/meshes/soft_gripper_finger1.stl"/>
		</geometry>
	</visual>
	<collision>
	    <origin rpy="0 0 0" xyz="0 0 0" />
		<geometry>
		    <mesh filename="robot_descriptions/gripper_description/gripper_description/meshes/soft_gripper_finger1.stl"/>
		</geometry>
	</collision>
    <inertial>
		<origin xyz="2.073e-05   1.45286e-03  -1.1049e-03" rpy="0 0 0" />
		<mass value="0.168" />
		<inertia ixx="6.69695624e-05" ixy="5.21511788e-09" ixz="-2.74383009e-08" iyy="7.85088161e-05" iyz="5.41105193e-07" izz="1.41819717e-04" />
	</inertial>
  </link>

  <joint name="hand2_joint2" type="fixed">
	<origin xyz="0 0.009 0.042" rpy=" 0 0 0" />
	<parent link="hand2_link" />
	<child link="hand2_link2" />
  </joint>

  <link name="hand2_link2">
	<visual>
		<geometry>
		  <mesh filename="robot_descriptions/gripper_description/gripper_description/meshes/soft_gripper_finger2.stl" />
		</geometry>
	    <material name="Blue" />
	</visual>
	<collision>
		<geometry>
		  <mesh filename="robot_descriptions/gripper_description/gripper_description/meshes/soft_gripper_finger2.stl" />
		</geometry>
	</collision>
	<inertial>
	    <origin xyz="2.073e-05   1.45286e-03  -1.1049e-03" rpy="0 0 0" />
		<mass value="0.168" />
		<inertia ixx="6.69695624e-05" ixy="5.21511788e-09" ixz="-2.74383009e-08" iyy="7.85088161e-05" iyz="5.41105193e-07" izz="1.41819717e-04" />
	</inertial>
  </link>

</robot>
